<?xml version="1.0" encoding="utf-8"?>
<!-- This URDF was automatically created by SolidWorks to URDF Exporter! Originally created by Stephen Brawner (brawner@gmail.com) 
     Commit Version: 1.6.0-1-g15f4949  Build Version: 1.6.7594.29634
     For more information, please see http://wiki.ros.org/sw_urdf_exporter -->
<robot
  name="hexapod">
  <link name="base_link"/>
    <joint name="j_phantomx_attachment" type="fixed">
    <parent link="base_link"/>
    <child link="BODY"/>
    <origin rpy="0 0 0" xyz="0 0 0"/>
  </joint>
  <link
    name="BODY">
    <inertial>
      <origin
        xyz="1.6123E-18 2.0011E-17 0.02"
        rpy="0 0 0" />
      <mass
        value="10.113" />
      <inertia
        ixx="0.017376"
        ixy="1.3248E-18"
        ixz="-2.583E-20"
        iyy="0.048968"
        iyz="4.6469E-19"
        izz="0.063647" />
    </inertial>
    <visual>
      <origin
        xyz="0 0 0"
        rpy="0 0 0" />
      <geometry>
        <mesh
          filename="package://hexapod/meshes/base_link.STL" />
      </geometry>
      <material
        name="">
        <color
          rgba="0.77647 0.75686 0.73725 1" />
      </material>
    </visual>
    <collision>
      <origin
        xyz="0 0 0"
        rpy="0 0 0" />
      <geometry>
        <mesh
          filename="package://hexapod/meshes/base_link.STL" />
      </geometry>
    </collision>
  </link>
  <link
    name="leg_0_1">
    <inertial>
      <origin
        xyz="-1.3878E-17 -0.044545 -3.4694E-18"
        rpy="0 0 0" />
      <mass
        value="0.72839" />
      <inertia
        ixx="0.00043937"
        ixy="-8.7578E-21"
        ixz="1.2531E-20"
        iyy="0.00019126"
        iyz="-6.4529E-20"
        izz="0.00034884" />
    </inertial>
    <visual>
      <origin
        xyz="0 0 0"
        rpy="0 0 0" />
      <geometry>
        <mesh
          filename="package://hexapod/meshes/leg_0_1.STL" />
      </geometry>
      <material
        name="">
        <color
          rgba="0.77647 0.75686 0.73725 1" />
      </material>
    </visual>
    <collision>
      <origin
        xyz="0 0 0"
        rpy="0 0 0" />
      <geometry>
        <mesh
          filename="package://hexapod/meshes/leg_0_1.STL" />
      </geometry>
    </collision>
  </link>
  <joint
    name="body_leg_0"
    type="continuous">
    <origin
      xyz="0.11 -0.06 0.02"
      rpy="0 0 0" />
    <parent
      link="base_link" />
    <child
      link="leg_0_1" />
    <axis
      xyz="0 0 1" />
    <limit
      lower="-1.57"
      upper="1.57"
      effort="30"
      velocity="3" />
  </joint>
  <link
    name="leg_0_2">
    <inertial>
      <origin
        xyz="1.0408E-17 0.058002 4.1633E-16"
        rpy="0 0 0" />
      <mass
        value="0.41845" />
      <inertia
        ixx="0.00026275"
        ixy="-4.5843E-20"
        ixz="1.1727E-21"
        iyy="4.7333E-05"
        iyz="1.0004E-20"
        izz="0.00026229" />
    </inertial>
    <visual>
      <origin
        xyz="0 0 0"
        rpy="0 0 0" />
      <geometry>
        <mesh
          filename="package://hexapod/meshes/leg_0_2.STL" />
      </geometry>
      <material
        name="">
        <color
          rgba="0.77647 0.75686 0.73725 1" />
      </material>
    </visual>
    <collision>
      <origin
        xyz="0 0 0"
        rpy="0 0 0" />
      <geometry>
        <mesh
          filename="package://hexapod/meshes/leg_0_2.STL" />
      </geometry>
    </collision>
  </link>
  <joint
    name="leg_0_1_2"
    type="revolute">
    <origin
      xyz="0 -0.08 0"
      rpy="3.1416 1.5708 0" />
    <parent
      link="leg_0_1" />
    <child
      link="leg_0_2" />
    <axis
      xyz="0 0 -1" />
    <limit
      lower="-1.57"
      upper="1.57"
      effort="30"
      velocity="3" />
  </joint>
  <link
    name="leg_0_3">
    <inertial>
      <origin
        xyz="0.084869 3.0882E-05 8.1879E-16"
        rpy="0 0 0" />
      <mass
        value="0.60411" />
      <inertia
        ixx="6.6228E-05"
        ixy="-9.4646E-08"
        ixz="-8.0496E-21"
        iyy="0.0010646"
        iyz="6.6317E-21"
        izz="0.0010259" />
    </inertial>
    <visual>
      <origin
        xyz="0 0 0"
        rpy="0 0 0" />
      <geometry>
        <mesh
          filename="package://hexapod/meshes/leg_0_3.STL" />
      </geometry>
      <material
        name="">
        <color
          rgba="0.77647 0.75686 0.73725 1" />
      </material>
    </visual>
    <collision>
      <origin
        xyz="0 0 0"
        rpy="0 0 0" />
      <geometry>
        <mesh
          filename="package://hexapod/meshes/leg_0_3.STL" />
      </geometry>
    </collision>
  </link>
  <joint
    name="leg_0_2_3"
    type="revolute">
    <origin
      xyz="0 0.1 0"
      rpy="0 0 0" />
    <parent
      link="leg_0_2" />
    <child
      link="leg_0_3" />
    <axis
      xyz="0 0 -1" />
    <limit
      lower="-1.57"
      upper="1.57"
      effort="30"
      velocity="3" />
  </joint>
  <link
    name="leg_1_1">
    <inertial>
      <origin
        xyz="8.3946E-19 -0.044545 -3.4694E-18"
        rpy="0 0 0" />
      <mass
        value="0.72839" />
      <inertia
        ixx="0.00043937"
        ixy="-5.1676E-21"
        ixz="1.8426E-20"
        iyy="0.00019126"
        iyz="-5.4987E-20"
        izz="0.00034884" />
    </inertial>
    <visual>
      <origin
        xyz="0 0 0"
        rpy="0 0 0" />
      <geometry>
        <mesh
          filename="package://hexapod/meshes/leg_1_1.STL" />
      </geometry>
      <material
        name="">
        <color
          rgba="0.77647 0.75686 0.73725 1" />
      </material>
    </visual>
    <collision>
      <origin
        xyz="0 0 0"
        rpy="0 0 0" />
      <geometry>
        <mesh
          filename="package://hexapod/meshes/leg_1_1.STL" />
      </geometry>
    </collision>
  </link>
  <joint
    name="body_leg_1"
    type="revolute">
    <origin
      xyz="0 -0.06 0.02"
      rpy="0 0 0" />
    <parent
      link="base_link" />
    <child
      link="leg_1_1" />
    <axis
      xyz="0 0 1" />
    <limit
      lower="-1.57"
      upper="1.57"
      effort="30"
      velocity="3" />
  </joint>
  <link
    name="leg_1_2">
    <inertial>
      <origin
        xyz="3.4694E-18 0.058002 6.9159E-16"
        rpy="0 0 0" />
      <mass
        value="0.41845" />
      <inertia
        ixx="0.00026275"
        ixy="-2.0171E-20"
        ixz="1.468E-21"
        iyy="4.7333E-05"
        iyz="1.2515E-22"
        izz="0.00026229" />
    </inertial>
    <visual>
      <origin
        xyz="0 0 0"
        rpy="0 0 0" />
      <geometry>
        <mesh
          filename="package://hexapod/meshes/leg_1_2.STL" />
      </geometry>
      <material
        name="">
        <color
          rgba="0.77647 0.75686 0.73725 1" />
      </material>
    </visual>
    <collision>
      <origin
        xyz="0 0 0"
        rpy="0 0 0" />
      <geometry>
        <mesh
          filename="package://hexapod/meshes/leg_1_2.STL" />
      </geometry>
    </collision>
  </link>
  <joint
    name="leg_1_1_2"
    type="revolute">
    <origin
      xyz="0 -0.08 0"
      rpy="3.1416 1.5708 0" />
    <parent
      link="leg_1_1" />
    <child
      link="leg_1_2" />
    <axis
      xyz="0 0 -1" />
    <limit
      lower="-1.57"
      upper="1.57"
      effort="30"
      velocity="3" />
  </joint>
  <link
    name="leg_1_3">
    <inertial>
      <origin
        xyz="0.084869 3.0882E-05 1.1215E-15"
        rpy="0 0 0" />
      <mass
        value="0.60411" />
      <inertia
        ixx="6.6228E-05"
        ixy="-9.4646E-08"
        ixz="1.4558E-20"
        iyy="0.0010646"
        iyz="6.946E-21"
        izz="0.0010259" />
    </inertial>
    <visual>
      <origin
        xyz="0 0 0"
        rpy="0 0 0" />
      <geometry>
        <mesh
          filename="package://hexapod/meshes/leg_1_3.STL" />
      </geometry>
      <material
        name="">
        <color
          rgba="0.77647 0.75686 0.73725 1" />
      </material>
    </visual>
    <collision>
      <origin
        xyz="0 0 0"
        rpy="0 0 0" />
      <geometry>
        <mesh
          filename="package://hexapod/meshes/leg_1_3.STL" />
      </geometry>
    </collision>
  </link>
  <joint
    name="leg_1_2_3"
    type="revolute">
    <origin
      xyz="0 0.1 0"
      rpy="0 0 0" />
    <parent
      link="leg_1_2" />
    <child
      link="leg_1_3" />
    <axis
      xyz="0 0 -1" />
    <limit
      lower="-1.57"
      upper="1.57"
      effort="30"
      velocity="3" />
  </joint>
  <link
    name="leg_2_1">
    <inertial>
      <origin
        xyz="0 -0.0445450847414412 -3.46944695195361E-18"
        rpy="0 0 0" />
      <mass
        value="0.728389334455051" />
      <inertia
        ixx="0.000439366489580605"
        ixy="-9.68414164900796E-21"
        ixz="1.25312997166837E-20"
        iyy="0.000191259700311432"
        iyz="-6.18146469128453E-20"
        izz="0.000348844779107573" />
    </inertial>
    <visual>
      <origin
        xyz="0 0 0"
        rpy="0 0 0" />
      <geometry>
        <mesh
          filename="package://hexapod/meshes/leg_2_1.STL" />
      </geometry>
      <material
        name="">
        <color
          rgba="0.776470588235294 0.756862745098039 0.737254901960784 1" />
      </material>
    </visual>
    <collision>
      <origin
        xyz="0 0 0"
        rpy="0 0 0" />
      <geometry>
        <mesh
          filename="package://hexapod/meshes/leg_2_1.STL" />
      </geometry>
    </collision>
  </link>
  <joint
    name="body_leg_2"
    type="revolute">
    <origin
      xyz="-0.11 -0.06 0.02"
      rpy="0 0 0" />
    <parent
      link="base_link" />
    <child
      link="leg_2_1" />
    <axis
      xyz="0 0 1" />
    <limit
      lower="-1.57"
      upper="1.57"
      effort="30"
      velocity="3" />
  </joint>
  <link
    name="leg_2_2">
    <inertial>
      <origin
        xyz="3.46944695195361E-18 0.0580015769708153 4.16333634234434E-16"
        rpy="0 0 0" />
      <mass
        value="0.418452411802267" />
      <inertia
        ixx="0.000262751554672186"
        ixy="-2.29707246501853E-20"
        ixz="1.17440633782818E-21"
        iyy="4.73331054250092E-05"
        iyz="8.90910991327263E-21"
        izz="0.000262289237082029" />
    </inertial>
    <visual>
      <origin
        xyz="0 0 0"
        rpy="0 0 0" />
      <geometry>
        <mesh
          filename="package://hexapod/meshes/leg_2_2.STL" />
      </geometry>
      <material
        name="">
        <color
          rgba="0.776470588235294 0.756862745098039 0.737254901960784 1" />
      </material>
    </visual>
    <collision>
      <origin
        xyz="0 0 0"
        rpy="0 0 0" />
      <geometry>
        <mesh
          filename="package://hexapod/meshes/leg_2_2.STL" />
      </geometry>
    </collision>
  </link>
  <joint
    name="leg_2_1_2"
    type="revolute">
    <origin
      xyz="0 -0.08 0"
      rpy="3.1416 1.5708 0" />
    <parent
      link="leg_2_1" />
    <child
      link="leg_2_2" />
    <axis
      xyz="0 0 -1" />
    <limit
      lower="-1.57"
      upper="1.57"
      effort="30"
      velocity="3" />
  </joint>
  <link
    name="leg_2_3">
    <inertial>
      <origin
        xyz="0.0848685291504994 3.08818446349557E-05 8.46545056276682E-16"
        rpy="0 0 0" />
      <mass
        value="0.604107235995325" />
      <inertia
        ixx="6.62284657464222E-05"
        ixy="-9.46460575317657E-08"
        ixz="-1.41036926063462E-20"
        iyy="0.0010645650517775"
        iyz="3.46274953425248E-21"
        izz="0.0010258729180328" />
    </inertial>
    <visual>
      <origin
        xyz="0 0 0"
        rpy="0 0 0" />
      <geometry>
        <mesh
          filename="package://hexapod/meshes/leg_2_3.STL" />
      </geometry>
      <material
        name="">
        <color
          rgba="0.776470588235294 0.756862745098039 0.737254901960784 1" />
      </material>
    </visual>
    <collision>
      <origin
        xyz="0 0 0"
        rpy="0 0 0" />
      <geometry>
        <mesh
          filename="package://hexapod/meshes/leg_2_3.STL" />
      </geometry>
    </collision>
  </link>
  <joint
    name="leg_2_2_3"
    type="revolute">
    <origin
      xyz="0 0.1 0"
      rpy="0 0 0" />
    <parent
      link="leg_2_2" />
    <child
      link="leg_2_3" />
    <axis
      xyz="0 0 -1" />
    <limit
      lower="-1.57"
      upper="1.57"
      effort="30"
      velocity="3" />
  </joint>
  <link
    name="leg_3_1">
    <inertial>
      <origin
        xyz="-3.33066907387547E-16 0.0445450847414412 -3.46944695195361E-18"
        rpy="0 0 0" />
      <mass
        value="0.728389334455052" />
      <inertia
        ixx="0.000439366489580605"
        ixy="1.73224222987974E-18"
        ixz="-1.04914228023895E-20"
        iyy="0.000191259700311432"
        iyz="5.99711139565986E-20"
        izz="0.000348844779107574" />
    </inertial>
    <visual>
      <origin
        xyz="0 0 0"
        rpy="0 0 0" />
      <geometry>
        <mesh
          filename="package://hexapod/meshes/leg_3_1.STL" />
      </geometry>
      <material
        name="">
        <color
          rgba="0.776470588235294 0.756862745098039 0.737254901960784 1" />
      </material>
    </visual>
    <collision>
      <origin
        xyz="0 0 0"
        rpy="0 0 0" />
      <geometry>
        <mesh
          filename="package://hexapod/meshes/leg_3_1.STL" />
      </geometry>
    </collision>
  </link>
  <joint
    name="body_leg_3"
    type="revolute">
    <origin
      xyz="-0.11 0.06 0.02"
      rpy="0 0 0" />
    <parent
      link="base_link" />
    <child
      link="leg_3_1" />
    <axis
      xyz="0 0 1" />
    <limit
      lower="-1.57"
      upper="1.57"
      effort="30"
      velocity="3" />
  </joint>
  <link
    name="leg_3_2">
    <inertial>
      <origin
        xyz="3.46944695195361E-18 0.0580015769708153 -1.52655665885959E-16"
        rpy="0 0 0" />
      <mass
        value="0.418452411802267" />
      <inertia
        ixx="0.000262751554672186"
        ixy="-3.19297811222879E-20"
        ixz="-1.82686702704007E-21"
        iyy="4.73331054250092E-05"
        iyz="3.83984040313595E-21"
        izz="0.000262289237082029" />
    </inertial>
    <visual>
      <origin
        xyz="0 0 0"
        rpy="0 0 0" />
      <geometry>
        <mesh
          filename="package://hexapod/meshes/leg_3_2.STL" />
      </geometry>
      <material
        name="">
        <color
          rgba="0.776470588235294 0.756862745098039 0.737254901960784 1" />
      </material>
    </visual>
    <collision>
      <origin
        xyz="0 0 0"
        rpy="0 0 0" />
      <geometry>
        <mesh
          filename="package://hexapod/meshes/leg_3_2.STL" />
      </geometry>
    </collision>
  </link>
  <joint
    name="leg_3_1_2"
    type="revolute">
    <origin
      xyz="0 0.08 0"
      rpy="0 1.5708 0" />
    <parent
      link="leg_3_1" />
    <child
      link="leg_3_2" />
    <axis
      xyz="0 0 -1" />
    <limit
      lower="-1.57"
      upper="1.57"
      effort="30"
      velocity="3" />
  </joint>
  <link
    name="leg_3_3">
    <inertial>
      <origin
        xyz="0.0848685291504994 3.08818446349002E-05 -4.44089209850063E-16"
        rpy="0 0 0" />
      <mass
        value="0.604107235995325" />
      <inertia
        ixx="6.62284657464222E-05"
        ixy="-9.46460575317819E-08"
        ixz="-1.36468729878862E-20"
        iyy="0.0010645650517775"
        iyz="1.69186859746484E-20"
        izz="0.0010258729180328" />
    </inertial>
    <visual>
      <origin
        xyz="0 0 0"
        rpy="0 0 0" />
      <geometry>
        <mesh
          filename="package://hexapod/meshes/leg_3_3.STL" />
      </geometry>
      <material
        name="">
        <color
          rgba="0.776470588235294 0.756862745098039 0.737254901960784 1" />
      </material>
    </visual>
    <collision>
      <origin
        xyz="0 0 0"
        rpy="0 0 0" />
      <geometry>
        <mesh
          filename="package://hexapod/meshes/leg_3_3.STL" />
      </geometry>
    </collision>
  </link>
  <joint
    name="leg_3_2_3"
    type="revolute">
    <origin
      xyz="0 0.1 0"
      rpy="0 0 0" />
    <parent
      link="leg_3_2" />
    <child
      link="leg_3_3" />
    <axis
      xyz="0 0 -1" />
    <limit
      lower="-1.57"
      upper="1.57"
      effort="30"
      velocity="3" />
  </joint>
  <link
    name="leg_4_1">
    <inertial>
      <origin
        xyz="-3.10207390283982E-16 0.0445450847414412 -3.46944695195361E-18"
        rpy="0 0 0" />
      <mass
        value="0.728389334455052" />
      <inertia
        ixx="0.000439366489580605"
        ixy="1.71212669776875E-18"
        ixz="-1.85376953020843E-20"
        iyy="0.000191259700311432"
        iyz="5.84109266813159E-20"
        izz="0.000348844779107574" />
    </inertial>
    <visual>
      <origin
        xyz="0 0 0"
        rpy="0 0 0" />
      <geometry>
        <mesh
          filename="package://hexapod/meshes/leg_4_1.STL" />
      </geometry>
      <material
        name="">
        <color
          rgba="0.776470588235294 0.756862745098039 0.737254901960784 1" />
      </material>
    </visual>
    <collision>
      <origin
        xyz="0 0 0"
        rpy="0 0 0" />
      <geometry>
        <mesh
          filename="package://hexapod/meshes/leg_4_1.STL" />
      </geometry>
    </collision>
  </link>
  <joint
    name="body_leg_4"
    type="revolute">
    <origin
      xyz="0 0.06 0.02"
      rpy="0 0 0" />
    <parent
      link="base_link" />
    <child
      link="leg_4_1" />
    <axis
      xyz="0 0 1" />
    <limit
      lower="-1.57"
      upper="1.57"
      effort="30"
      velocity="3" />
  </joint>
  <link
    name="leg_4_2">
    <inertial>
      <origin
        xyz="1.38777878078145E-17 0.0580015769708153 -4.44383469065972E-16"
        rpy="0 0 0" />
      <mass
        value="0.418452411802267" />
      <inertia
        ixx="0.000262751554672186"
        ixy="-5.39530835154313E-20"
        ixz="1.85302270824603E-21"
        iyy="4.73331054250092E-05"
        iyz="4.22125501442446E-21"
        izz="0.000262289237082029" />
    </inertial>
    <visual>
      <origin
        xyz="0 0 0"
        rpy="0 0 0" />
      <geometry>
        <mesh
          filename="package://hexapod/meshes/leg_4_2.STL" />
      </geometry>
      <material
        name="">
        <color
          rgba="0.776470588235294 0.756862745098039 0.737254901960784 1" />
      </material>
    </visual>
    <collision>
      <origin
        xyz="0 0 0"
        rpy="0 0 0" />
      <geometry>
        <mesh
          filename="package://hexapod/meshes/leg_4_2.STL" />
      </geometry>
    </collision>
  </link>
  <joint
    name="leg_4_1_2"
    type="revolute">
    <origin
      xyz="0 0.08 0"
      rpy="0 1.5708 0" />
    <parent
      link="leg_4_1" />
    <child
      link="leg_4_2" />
    <axis
      xyz="0 0 -1" />
    <limit
      lower="-1.57"
      upper="1.57"
      effort="30"
      velocity="3" />
  </joint>
  <link
    name="leg_4_3">
    <inertial>
      <origin
        xyz="0.0848685291504994 3.08818446349279E-05 -7.27946480685188E-16"
        rpy="0 0 0" />
      <mass
        value="0.604107235995325" />
      <inertia
        ixx="6.62284657464222E-05"
        ixy="-9.46460575317807E-08"
        ixz="8.79682739135738E-21"
        iyy="0.0010645650517775"
        iyz="1.06402762826064E-20"
        izz="0.0010258729180328" />
    </inertial>
    <visual>
      <origin
        xyz="0 0 0"
        rpy="0 0 0" />
      <geometry>
        <mesh
          filename="package://hexapod/meshes/leg_4_3.STL" />
      </geometry>
      <material
        name="">
        <color
          rgba="0.776470588235294 0.756862745098039 0.737254901960784 1" />
      </material>
    </visual>
    <collision>
      <origin
        xyz="0 0 0"
        rpy="0 0 0" />
      <geometry>
        <mesh
          filename="package://hexapod/meshes/leg_4_3.STL" />
      </geometry>
    </collision>
  </link>
  <joint
    name="leg_4_2_3"
    type="revolute">
    <origin
      xyz="0 0.1 0"
      rpy="0 0 0" />
    <parent
      link="leg_4_2" />
    <child
      link="leg_4_3" />
    <axis
      xyz="0 0 -1" />
    <limit
      lower="-1.57"
      upper="1.57"
      effort="30"
      velocity="3" />
  </joint>
  <link
    name="leg_5_1">
    <inertial>
      <origin
        xyz="-3.05311331771918E-16 0.0445450847414412 -3.46944695195361E-18"
        rpy="0 0 0" />
      <mass
        value="0.728389334455052" />
      <inertia
        ixx="0.000439366489580605"
        ixy="1.73270541333655E-18"
        ixz="-1.04894919526316E-20"
        iyy="0.000191259700311432"
        iyz="6.32437500027912E-20"
        izz="0.000348844779107574" />
    </inertial>
    <visual>
      <origin
        xyz="0 0 0"
        rpy="0 0 0" />
      <geometry>
        <mesh
          filename="package://hexapod/meshes/leg_5_1.STL" />
      </geometry>
      <material
        name="">
        <color
          rgba="0.776470588235294 0.756862745098039 0.737254901960784 1" />
      </material>
    </visual>
    <collision>
      <origin
        xyz="0 0 0"
        rpy="0 0 0" />
      <geometry>
        <mesh
          filename="package://hexapod/meshes/leg_5_1.STL" />
      </geometry>
    </collision>
  </link>
  <joint
    name="body_leg_5"
    type="revolute">
    <origin
      xyz="0.11 0.06 0.02"
      rpy="0 0 0" />
    <parent
      link="base_link" />
    <child
      link="leg_5_1" />
    <axis
      xyz="0 0 1" />
    <limit
      lower="-1.57"
      upper="1.57"
      effort="30"
      velocity="3" />
  </joint>
  <link
    name="leg_5_2">
    <inertial>
      <origin
        xyz="1.04083408558608E-17 0.0580015769708153 -1.2490009027033E-16"
        rpy="0 0 0" />
      <mass
        value="0.418452411802267" />
      <inertia
        ixx="0.000262751554672186"
        ixy="-5.50747586323413E-20"
        ixz="-1.83205374665578E-21"
        iyy="4.73331054250092E-05"
        iyz="3.64508569336397E-21"
        izz="0.000262289237082029" />
    </inertial>
    <visual>
      <origin
        xyz="0 0 0"
        rpy="0 0 0" />
      <geometry>
        <mesh
          filename="package://hexapod/meshes/leg_5_2.STL" />
      </geometry>
      <material
        name="">
        <color
          rgba="0.776470588235294 0.756862745098039 0.737254901960784 1" />
      </material>
    </visual>
    <collision>
      <origin
        xyz="0 0 0"
        rpy="0 0 0" />
      <geometry>
        <mesh
          filename="package://hexapod/meshes/leg_5_2.STL" />
      </geometry>
    </collision>
  </link>
  <joint
    name="leg_5_1_2"
    type="revolute">
    <origin
      xyz="0 0.08 0"
      rpy="0 1.5708 0" />
    <parent
      link="leg_5_1" />
    <child
      link="leg_5_2" />
    <axis
      xyz="0 0 -1" />
    <limit
      lower="-1.57"
      upper="1.57"
      effort="30"
      velocity="3" />
  </joint>
  <link
    name="leg_5_3">
    <inertial>
      <origin
        xyz="0.084869 3.0882E-05 -4.4409E-16"
        rpy="0 0 0" />
      <mass
        value="0.60411" />
      <inertia
        ixx="6.6228E-05"
        ixy="-9.4646E-08"
        ixz="1.4534E-22"
        iyy="0.0010646"
        iyz="1.5418E-20"
        izz="0.0010259" />
    </inertial>
    <visual>
      <origin
        xyz="0 0 0"
        rpy="0 0 0" />
      <geometry>
        <mesh
          filename="package://hexapod/meshes/leg_5_3.STL" />
      </geometry>
      <material
        name="">
        <color
          rgba="0.77647 0.75686 0.73725 1" />
      </material>
    </visual>
    <collision>
      <origin
        xyz="0 0 0"
        rpy="0 0 0" />
      <geometry>
        <mesh
          filename="package://hexapod/meshes/leg_5_3.STL" />
      </geometry>
    </collision>
  </link>
  <joint
    name="leg_5_2_3"
    type="revolute">
    <origin
      xyz="0 0.1 0"
      rpy="0 0 0" />
    <parent
      link="leg_5_2" />
    <child
      link="leg_5_3" />
    <axis
      xyz="0 0 -1" />
    <limit
      lower="-1.57"
      upper="1.57"
      effort="30"
      velocity="3" />
  </joint>
</robot>